2022-03-09 07:23:07,934 - django.request - ERROR - Internal Server Error: /appointments/specialities/
Traceback (most recent call last):
  File "/home/er/Desktop/Appointment-Booking-System/AppointmentBookingSystem/appointments/views.py", line 23, in get
    doctors = User.objects.filter(role=ROLE[10][0])
IndexError: tuple index out of range

During handling of the above exception, another exception occurred:

Traceback (most recent call last):
  File "/home/er/.local/lib/python3.6/site-packages/django/core/handlers/exception.py", line 47, in inner
    response = get_response(request)
  File "/home/er/.local/lib/python3.6/site-packages/django/core/handlers/base.py", line 181, in _get_response
    response = wrapped_callback(request, *callback_args, **callback_kwargs)
  File "/home/er/.local/lib/python3.6/site-packages/django/views/generic/base.py", line 70, in view
    return self.dispatch(request, *args, **kwargs)
  File "/home/er/.local/lib/python3.6/site-packages/django/contrib/auth/mixins.py", line 71, in dispatch
    return super().dispatch(request, *args, **kwargs)
  File "/home/er/.local/lib/python3.6/site-packages/django/views/generic/base.py", line 98, in dispatch
    return handler(request, *args, **kwargs)
  File "/home/er/Desktop/Appointment-Booking-System/AppointmentBookingSystem/appointments/views.py", line 29, in get
    AppLogger().log_error(var)
  File "/home/er/Desktop/Appointment-Booking-System/AppointmentBookingSystem/AppointmentBookingSystem/logger.py", line 33, in __init__
    self.logging.addHandler(self.rotating_file_handler)
AttributeError: 'AppLogger' object has no attribute 'logging'
2022-03-09 07:23:08,056 - django.request - WARNING - Not Found: /favicon.ico
2022-03-09 07:23:55,329 - django.utils.autoreload - INFO - /home/er/Desktop/Appointment-Booking-System/AppointmentBookingSystem/AppointmentBookingSystem/logger.py changed, reloading.
2022-03-09 07:41:06,203 - root - ERROR - {'class_name': 'SpecialitiesView', 'method_name': 'GET', 'errors': IndexError('tuple index out of range',)}
2022-03-09 07:41:49,926 - django.utils.autoreload - INFO - /home/er/Desktop/Appointment-Booking-System/AppointmentBookingSystem/AppointmentBookingSystem/logger.py changed, reloading.
2022-03-09 07:53:49,945 - root - ERROR - {'class_name': 'SpecialitiesView', 'method_name': 'GET', 'errors': IndexError('tuple index out of range',)}
2022-03-09 07:55:04,426 - django.utils.autoreload - INFO - /home/er/Desktop/Appointment-Booking-System/AppointmentBookingSystem/AppointmentBookingSystem/logger.py changed, reloading.
2022-03-09 07:55:36,854 - root - ERROR - {'class_name': 'SpecialitiesView', 'method_name': 'GET', 'errors': IndexError('tuple index out of range',)}
2022-03-09 07:58:01,327 - django.utils.autoreload - INFO - /home/er/Desktop/Appointment-Booking-System/AppointmentBookingSystem/AppointmentBookingSystem/logger.py changed, reloading.
2022-03-09 07:58:22,085 - root - ERROR - {'class_name': 'SpecialitiesView', 'method_name': 'GET', 'errors': IndexError('tuple index out of range',)}
2022-03-09 08:21:46,458 - root - ERROR - {'class_name': 'SpecialitiesView', 'method_name': 'GET', 'errors': IndexError('tuple index out of range',)}
2022-03-09 08:21:46,458 - root - ERROR - {'class_name': 'SpecialitiesView', 'method_name': 'GET', 'errors': IndexError('tuple index out of range',)}
2022-03-09 08:22:25,815 - django.utils.autoreload - INFO - /home/er/Desktop/Appointment-Booking-System/AppointmentBookingSystem/AppointmentBookingSystem/logger.py changed, reloading.
2022-03-09 08:22:25,815 - django.utils.autoreload - INFO - /home/er/Desktop/Appointment-Booking-System/AppointmentBookingSystem/AppointmentBookingSystem/logger.py changed, reloading.
2022-03-09 08:22:32,413 - root - ERROR - {'class_name': 'SpecialitiesView', 'method_name': 'GET', 'errors': IndexError('tuple index out of range',)}
2022-03-09 08:23:39,086 - django.request - ERROR - Internal Server Error: /accounts/add_doctor/
Traceback (most recent call last):
  File "/home/er/.local/lib/python3.6/site-packages/kombu/serialization.py", line 42, in _reraise_errors
    yield
  File "/home/er/.local/lib/python3.6/site-packages/kombu/serialization.py", line 213, in dumps
    payload = encoder(data)
  File "/home/er/.local/lib/python3.6/site-packages/kombu/utils/json.py", line 69, in dumps
    **dict(default_kwargs, **kwargs))
  File "/usr/lib/python3/dist-packages/simplejson/__init__.py", line 399, in dumps
    **kw).encode(obj)
  File "/usr/lib/python3/dist-packages/simplejson/encoder.py", line 291, in encode
    chunks = self.iterencode(o, _one_shot=True)
  File "/usr/lib/python3/dist-packages/simplejson/encoder.py", line 373, in iterencode
    return _iterencode(o, 0)
  File "/home/er/.local/lib/python3.6/site-packages/kombu/utils/json.py", line 58, in default
    return super().default(o)
  File "/usr/lib/python3/dist-packages/simplejson/encoder.py", line 268, in default
    o.__class__.__name__)
TypeError: Object of type AddDoctorView is not JSON serializable

During handling of the above exception, another exception occurred:

Traceback (most recent call last):
  File "/home/er/Desktop/Appointment-Booking-System/AppointmentBookingSystem/accounts/views.py", line 35, in post
    send_invitation_email.delay(self, userdata)
  File "/home/er/.local/lib/python3.6/site-packages/celery/app/task.py", line 422, in delay
    return self.apply_async(args, kwargs)
  File "/home/er/.local/lib/python3.6/site-packages/celery/app/task.py", line 576, in apply_async
    **options
  File "/home/er/.local/lib/python3.6/site-packages/celery/app/base.py", line 767, in send_task
    amqp.send_task_message(P, name, message, **options)
  File "/home/er/.local/lib/python3.6/site-packages/celery/app/amqp.py", line 519, in send_task_message
    **properties
  File "/home/er/.local/lib/python3.6/site-packages/kombu/messaging.py", line 168, in publish
    compression, headers)
  File "/home/er/.local/lib/python3.6/site-packages/kombu/messaging.py", line 254, in _prepare
    body) = dumps(body, serializer=serializer)
  File "/home/er/.local/lib/python3.6/site-packages/kombu/serialization.py", line 213, in dumps
    payload = encoder(data)
  File "/usr/lib/python3.6/contextlib.py", line 99, in __exit__
    self.gen.throw(type, value, traceback)
  File "/home/er/.local/lib/python3.6/site-packages/kombu/serialization.py", line 46, in _reraise_errors
    reraise(wrapper, wrapper(exc), sys.exc_info()[2])
  File "/home/er/.local/lib/python3.6/site-packages/kombu/exceptions.py", line 21, in reraise
    raise value.with_traceback(tb)
  File "/home/er/.local/lib/python3.6/site-packages/kombu/serialization.py", line 42, in _reraise_errors
    yield
  File "/home/er/.local/lib/python3.6/site-packages/kombu/serialization.py", line 213, in dumps
    payload = encoder(data)
  File "/home/er/.local/lib/python3.6/site-packages/kombu/utils/json.py", line 69, in dumps
    **dict(default_kwargs, **kwargs))
  File "/usr/lib/python3/dist-packages/simplejson/__init__.py", line 399, in dumps
    **kw).encode(obj)
  File "/usr/lib/python3/dist-packages/simplejson/encoder.py", line 291, in encode
    chunks = self.iterencode(o, _one_shot=True)
  File "/usr/lib/python3/dist-packages/simplejson/encoder.py", line 373, in iterencode
    return _iterencode(o, 0)
  File "/home/er/.local/lib/python3.6/site-packages/kombu/utils/json.py", line 58, in default
    return super().default(o)
  File "/usr/lib/python3/dist-packages/simplejson/encoder.py", line 268, in default
    o.__class__.__name__)
kombu.exceptions.EncodeError: Object of type AddDoctorView is not JSON serializable

During handling of the above exception, another exception occurred:

Traceback (most recent call last):
  File "/home/er/.local/lib/python3.6/site-packages/django/core/handlers/exception.py", line 47, in inner
    response = get_response(request)
  File "/home/er/.local/lib/python3.6/site-packages/django/core/handlers/base.py", line 181, in _get_response
    response = wrapped_callback(request, *callback_args, **callback_kwargs)
  File "/home/er/.local/lib/python3.6/site-packages/django/views/generic/base.py", line 70, in view
    return self.dispatch(request, *args, **kwargs)
  File "/home/er/.local/lib/python3.6/site-packages/django/contrib/auth/mixins.py", line 71, in dispatch
    return super().dispatch(request, *args, **kwargs)
  File "/home/er/.local/lib/python3.6/site-packages/django/views/generic/base.py", line 98, in dispatch
    return handler(request, *args, **kwargs)
  File "/home/er/Desktop/Appointment-Booking-System/AppointmentBookingSystem/accounts/views.py", line 41, in post
    AppLogger().log_error(e, class_object=self)
  File "/home/er/Desktop/Appointment-Booking-System/AppointmentBookingSystem/AppointmentBookingSystem/logger.py", line 94, in log_error
    self.async_logger(func=self.logger.error, msg=self.data_formatter(e))
  File "/home/er/Desktop/Appointment-Booking-System/AppointmentBookingSystem/AppointmentBookingSystem/logger.py", line 80, in data_formatter
    class_name=e['class_object'].__class__.__name__,
TypeError: 'EncodeError' object is not subscriptable
2022-03-09 08:23:39,086 - django.request - ERROR - Internal Server Error: /accounts/add_doctor/
Traceback (most recent call last):
  File "/home/er/.local/lib/python3.6/site-packages/kombu/serialization.py", line 42, in _reraise_errors
    yield
  File "/home/er/.local/lib/python3.6/site-packages/kombu/serialization.py", line 213, in dumps
    payload = encoder(data)
  File "/home/er/.local/lib/python3.6/site-packages/kombu/utils/json.py", line 69, in dumps
    **dict(default_kwargs, **kwargs))
  File "/usr/lib/python3/dist-packages/simplejson/__init__.py", line 399, in dumps
    **kw).encode(obj)
  File "/usr/lib/python3/dist-packages/simplejson/encoder.py", line 291, in encode
    chunks = self.iterencode(o, _one_shot=True)
  File "/usr/lib/python3/dist-packages/simplejson/encoder.py", line 373, in iterencode
    return _iterencode(o, 0)
  File "/home/er/.local/lib/python3.6/site-packages/kombu/utils/json.py", line 58, in default
    return super().default(o)
  File "/usr/lib/python3/dist-packages/simplejson/encoder.py", line 268, in default
    o.__class__.__name__)
TypeError: Object of type AddDoctorView is not JSON serializable

During handling of the above exception, another exception occurred:

Traceback (most recent call last):
  File "/home/er/Desktop/Appointment-Booking-System/AppointmentBookingSystem/accounts/views.py", line 35, in post
    send_invitation_email.delay(self, userdata)
  File "/home/er/.local/lib/python3.6/site-packages/celery/app/task.py", line 422, in delay
    return self.apply_async(args, kwargs)
  File "/home/er/.local/lib/python3.6/site-packages/celery/app/task.py", line 576, in apply_async
    **options
  File "/home/er/.local/lib/python3.6/site-packages/celery/app/base.py", line 767, in send_task
    amqp.send_task_message(P, name, message, **options)
  File "/home/er/.local/lib/python3.6/site-packages/celery/app/amqp.py", line 519, in send_task_message
    **properties
  File "/home/er/.local/lib/python3.6/site-packages/kombu/messaging.py", line 168, in publish
    compression, headers)
  File "/home/er/.local/lib/python3.6/site-packages/kombu/messaging.py", line 254, in _prepare
    body) = dumps(body, serializer=serializer)
  File "/home/er/.local/lib/python3.6/site-packages/kombu/serialization.py", line 213, in dumps
    payload = encoder(data)
  File "/usr/lib/python3.6/contextlib.py", line 99, in __exit__
    self.gen.throw(type, value, traceback)
  File "/home/er/.local/lib/python3.6/site-packages/kombu/serialization.py", line 46, in _reraise_errors
    reraise(wrapper, wrapper(exc), sys.exc_info()[2])
  File "/home/er/.local/lib/python3.6/site-packages/kombu/exceptions.py", line 21, in reraise
    raise value.with_traceback(tb)
  File "/home/er/.local/lib/python3.6/site-packages/kombu/serialization.py", line 42, in _reraise_errors
    yield
  File "/home/er/.local/lib/python3.6/site-packages/kombu/serialization.py", line 213, in dumps
    payload = encoder(data)
  File "/home/er/.local/lib/python3.6/site-packages/kombu/utils/json.py", line 69, in dumps
    **dict(default_kwargs, **kwargs))
  File "/usr/lib/python3/dist-packages/simplejson/__init__.py", line 399, in dumps
    **kw).encode(obj)
  File "/usr/lib/python3/dist-packages/simplejson/encoder.py", line 291, in encode
    chunks = self.iterencode(o, _one_shot=True)
  File "/usr/lib/python3/dist-packages/simplejson/encoder.py", line 373, in iterencode
    return _iterencode(o, 0)
  File "/home/er/.local/lib/python3.6/site-packages/kombu/utils/json.py", line 58, in default
    return super().default(o)
  File "/usr/lib/python3/dist-packages/simplejson/encoder.py", line 268, in default
    o.__class__.__name__)
kombu.exceptions.EncodeError: Object of type AddDoctorView is not JSON serializable

During handling of the above exception, another exception occurred:

Traceback (most recent call last):
  File "/home/er/.local/lib/python3.6/site-packages/django/core/handlers/exception.py", line 47, in inner
    response = get_response(request)
  File "/home/er/.local/lib/python3.6/site-packages/django/core/handlers/base.py", line 181, in _get_response
    response = wrapped_callback(request, *callback_args, **callback_kwargs)
  File "/home/er/.local/lib/python3.6/site-packages/django/views/generic/base.py", line 70, in view
    return self.dispatch(request, *args, **kwargs)
  File "/home/er/.local/lib/python3.6/site-packages/django/contrib/auth/mixins.py", line 71, in dispatch
    return super().dispatch(request, *args, **kwargs)
  File "/home/er/.local/lib/python3.6/site-packages/django/views/generic/base.py", line 98, in dispatch
    return handler(request, *args, **kwargs)
  File "/home/er/Desktop/Appointment-Booking-System/AppointmentBookingSystem/accounts/views.py", line 41, in post
    AppLogger().log_error(e, class_object=self)
  File "/home/er/Desktop/Appointment-Booking-System/AppointmentBookingSystem/AppointmentBookingSystem/logger.py", line 94, in log_error
    self.async_logger(func=self.logger.error, msg=self.data_formatter(e))
  File "/home/er/Desktop/Appointment-Booking-System/AppointmentBookingSystem/AppointmentBookingSystem/logger.py", line 80, in data_formatter
    class_name=e['class_object'].__class__.__name__,
TypeError: 'EncodeError' object is not subscriptable
2022-03-09 08:23:39,270 - django.request - WARNING - Not Found: /favicon.ico
2022-03-09 08:23:39,270 - django.request - WARNING - Not Found: /favicon.ico
2022-03-09 08:24:33,175 - django.utils.autoreload - INFO - /home/er/Desktop/Appointment-Booking-System/AppointmentBookingSystem/accounts/views.py changed, reloading.
2022-03-09 08:24:33,175 - django.utils.autoreload - INFO - /home/er/Desktop/Appointment-Booking-System/AppointmentBookingSystem/accounts/views.py changed, reloading.
2022-03-09 08:26:45,477 - root - ERROR - {'class_name': 'AddDoctorView', 'method_name': 'POST', 'errors': EncodeError(TypeError('Object of type AddDoctorView is not JSON serializable',),)}
2022-03-09 08:28:20,891 - django.utils.autoreload - INFO - /home/er/Desktop/Appointment-Booking-System/AppointmentBookingSystem/AppointmentBookingSystem/logger.py changed, reloading.
2022-03-09 08:29:52,322 - root - ERROR - {'class_name': 'SpecialitiesView', 'method_name': 'GET', 'errors': IndexError('tuple index out of range',)}
2022-03-09 08:30:02,587 - root - ERROR - {'class_name': 'SpecialitiesView', 'method_name': 'GET', 'errors': IndexError('tuple index out of range',)}
2022-03-09 08:30:02,587 - root - ERROR - {'class_name': 'SpecialitiesView', 'method_name': 'GET', 'errors': IndexError('tuple index out of range',)}
2022-03-09 08:43:38,152 - django.utils.autoreload - INFO - /home/er/Desktop/Appointment-Booking-System/AppointmentBookingSystem/AppointmentBookingSystem/logger.py changed, reloading.
2022-03-09 08:43:38,152 - django.utils.autoreload - INFO - /home/er/Desktop/Appointment-Booking-System/AppointmentBookingSystem/AppointmentBookingSystem/logger.py changed, reloading.
2022-03-09 08:43:39,310 - root - ERROR - {'class_name': 'SpecialitiesView', 'method_name': 'GET', 'errors': IndexError('tuple index out of range',)}
2022-03-09 08:46:57,318 - root - ERROR - {'class_name': 'SpecialitiesView', 'method_name': 'GET', 'errors': IndexError('tuple index out of range',)}
2022-03-09 08:47:01,739 - root - ERROR - {'class_name': 'SpecialitiesView', 'method_name': 'GET', 'errors': IndexError('tuple index out of range',)}
2022-03-09 08:47:01,739 - root - ERROR - {'class_name': 'SpecialitiesView', 'method_name': 'GET', 'errors': IndexError('tuple index out of range',)}
2022-03-09 08:47:10,490 - root - ERROR - {'class_name': 'SpecialitiesView', 'method_name': 'GET', 'errors': IndexError('tuple index out of range',)}
2022-03-09 08:47:10,490 - root - ERROR - {'class_name': 'SpecialitiesView', 'method_name': 'GET', 'errors': IndexError('tuple index out of range',)}
2022-03-09 08:47:10,490 - root - ERROR - {'class_name': 'SpecialitiesView', 'method_name': 'GET', 'errors': IndexError('tuple index out of range',)}
2022-03-09 09:30:49,832 - django.utils.autoreload - INFO - /home/er/Desktop/Appointment-Booking-System/AppointmentBookingSystem/AppointmentBookingSystem/logger.py changed, reloading.
2022-03-09 09:30:49,832 - django.utils.autoreload - INFO - /home/er/Desktop/Appointment-Booking-System/AppointmentBookingSystem/AppointmentBookingSystem/logger.py changed, reloading.
2022-03-09 09:30:49,832 - django.utils.autoreload - INFO - /home/er/Desktop/Appointment-Booking-System/AppointmentBookingSystem/AppointmentBookingSystem/logger.py changed, reloading.
2022-03-09 09:30:58,969 - root - ERROR - {'class_name': 'SpecialitiesView', 'method_name': 'GET', 'errors': IndexError('tuple index out of range',)}
2022-03-09 10:03:04,919 - AppointmentBookingSystem.logger - ERROR - {'class_name': 'SpecialitiesView', 'method_name': 'GET', 'errors': IndexError('tuple index out of range',)}
2022-03-09 10:03:42,744 - AppointmentBookingSystem.logger - ERROR - {'class_name': 'SpecialitiesView', 'method_name': 'GET', 'errors': IndexError('tuple index out of range',)}
2022-03-09 10:05:31,093 - AppointmentBookingSystem.logger - ERROR - {'class_name': 'SpecialitiesView', 'method_name': 'GET', 'errors': IndexError('tuple index out of range',)}
2022-03-09 15:38:06,238 - AppointmentBookingSystem.logger - ERROR - {'class_name': 'SpecialitiesView', 'method_name': 'GET', 'errors': IndexError('tuple index out of range',)}
2022-03-09 15:47:39,905 - AppointmentBookingSystem.logger - ERROR - {'class_name': 'SpecialitiesView', 'method_name': 'GET', 'errors': IndexError('tuple index out of range',)}
2022-03-09 15:47:53,958 - AppointmentBookingSystem.logger - ERROR - {'class_name': 'SpecialitiesView', 'method_name': 'GET', 'errors': IndexError('tuple index out of range',)}
2022-03-09 16:29:37,917 - AppointmentBookingSystem.logger - ERROR - {'class_name': 'SpecialitiesView', 'method_name': 'GET', 'errors': IndexError('tuple index out of range',)}
03/09/2022 04:29:37 PM - AppointmentBookingSystem.logger - ERROR - {'class_name': 'SpecialitiesView', 'method_name': 'GET', 'errors': IndexError('tuple index out of range',)}
2022-03-09 16:29:45,009 - AppointmentBookingSystem.logger - ERROR - {'class_name': 'SpecialitiesView', 'method_name': 'GET', 'errors': IndexError('tuple index out of range',)}
03/09/2022 04:29:45 PM - AppointmentBookingSystem.logger - ERROR - {'class_name': 'SpecialitiesView', 'method_name': 'GET', 'errors': IndexError('tuple index out of range',)}
2022-03-09 16:29:48,209 - AppointmentBookingSystem.logger - ERROR - {'class_name': 'SpecialitiesView', 'method_name': 'GET', 'errors': IndexError('tuple index out of range',)}
03/09/2022 04:29:48 PM - AppointmentBookingSystem.logger - ERROR - {'class_name': 'SpecialitiesView', 'method_name': 'GET', 'errors': IndexError('tuple index out of range',)}
2022-03-09 16:29:51,755 - AppointmentBookingSystem.logger - ERROR - {'class_name': 'SpecialitiesView', 'method_name': 'GET', 'errors': IndexError('tuple index out of range',)}
03/09/2022 04:29:51 PM - AppointmentBookingSystem.logger - ERROR - {'class_name': 'SpecialitiesView', 'method_name': 'GET', 'errors': IndexError('tuple index out of range',)}
2022-03-09 16:30:03,290 - AppointmentBookingSystem.logger - ERROR - {'class_name': 'SpecialitiesView', 'method_name': 'GET', 'errors': IndexError('tuple index out of range',)}
03/09/2022 04:30:03 PM - AppointmentBookingSystem.logger - ERROR - {'class_name': 'SpecialitiesView', 'method_name': 'GET', 'errors': IndexError('tuple index out of range',)}
03/09/2022 04:30:29 PM - django.utils.autoreload - INFO - /home/er/Desktop/Appointment-Booking-System/AppointmentBookingSystem/AppointmentBookingSystem/logger.py changed, reloading.
2022-03-09 16:30:30,258 - AppointmentBookingSystem.logger - ERROR - {'class_name': 'SpecialitiesView', 'method_name': 'GET', 'errors': IndexError('tuple index out of range',)}
2022-03-09 16:30:34,866 - AppointmentBookingSystem.logger - ERROR - {'class_name': 'SpecialitiesView', 'method_name': 'GET', 'errors': IndexError('tuple index out of range',)}
